Workbook
Name zsupermetrics_refreshAll: SupermetricsQueries!$H$5
Name zsupermetrics_xhBK48cDeYRNkKTgEkN3NSS83QBpNp: TK!$H$6:$S$65
Name zsupermetrics_forceRefresh: SupermetricsQueries!$H$4
Name zsupermetrics_refreshAllSilent: SupermetricsQueries!$H$6

Sheet DATOS MENSUALES
A1: ENERO
A3: PRODUCTO | B3: VENTAS | C3: PROVEEDOR | D3: LOGISTICA | E3: DEVOLUCION | F3: TIK TOK ADS | G3: FACEBOOK ADS | H3: M PRIMA | I3: UTILIDAD | J3: =IFERROR( IF(OR($K10=0, SUM($J10:P10)=0), "", "ENTREGAS "&TEXT(J10/SUM($J10:P10), "0%")) ,"") -> ENTREGAS 54% | K3: =IFERROR( IF(OR($K10=0, SUM($J10:P10)=0), "", "DEVOLUCION "&TEXT(K10/SUM($J10:P10), "0%")) ,"") -> DEVOLUCION 22% | L3: =IFERROR( IF(OR($K10=0, SUM($J10:P10)=0), "", "PROCESO "&TEXT(L10/SUM($J10:P10), "0%")) ,"") -> PROCESO 0% | M3: =IFERROR( IF(OR($K10=0, SUM($J10:P10)=0), "", "NOVEDAD "&TEXT(M10/SUM($J10:P10), "0%")) ,"") -> NOVEDAD 0% | N3: =IFERROR( IF(OR($K10=0, SUM($J10:P10)=0), "", "PENDIENTES "&TEXT(N10/SUM($J10:P10), "0%")) ,"") -> PENDIENTES 14% | O3: =IFERROR( IF(OR($K10=0, SUM($J10:P10)=0), "", "CANCELADOS "&TEXT(O10/SUM($J10:P10), "0%")) ,"") -> CANCELADOS 7% | P3: =IFERROR( IF(OR($K10=0, SUM($J10:P10)=0), "", "REVISAR "&TEXT(P10/SUM($J10:P10), "0%")) ,"") -> REVISAR 3%
A4: =IFERROR(__xludf.DUMMYFUNCTION("UNIQUE( FILTER( TRIM( FLATTEN( SPLIT(ENERO!D2:D1000, "";"") ) ), FLATTEN( SPLIT(ENERO!D2:D1000, "";"") )<>"""" ) )"),"Llave Multifuncional 360™") -> Llave Multifuncional 360™ | B4: =IF(A4="","",SUMIF(ENERO!D:D, A4, ENERO!G:G)) -> 1519.75 | C4: =IF(A4="","",SUMIF(ENERO!D:D, A4, ENERO!E:E)) -> 485 | D4: =IF(A4="","",SUMIF(ENERO!D:D, A4, ENERO!J:J)) -> 345.33 | E4: =IF(A4="","",SUMIF(ENERO!D:D, A4, ENERO!L:L)) -> 115.45 | F4: =IFERROR(__xludf.DUMMYFUNCTION("IFERROR( IF(A4="""","""",SUM( FILTER( VALUE(SUBSTITUTE(TK!B:B,""."","","")), REGEXMATCH(TK!A:A,A4), MONTH( DATE( VALUE(RIGHT(LEFT(TK!A:A,10),4)), VALUE(MID(TK!A:A,4,2)), VALUE(LEFT(TK!A:A,2)) ) )=1 ) )), """") "),0.0) -> 0 | G4: =IFERROR(__xludf.DUMMYFUNCTION("IF( A4="""", """", SUM( FILTER( VALUE(SUBSTITUTE(FB!D:D, ""."", "","")), REGEXMATCH(FB!B:B, A4), MONTH(FB!E:E)=1 ) ) * 1.2 ) "),525.564) -> 525.564 | I4: =IF(A4="","",B4-SUM(C4:G4)) -> 48.406 | J4: =IF(A4="","",COUNTIFS(ENERO!D:D,A4,ENERO!O:O,"ENTREGADO")) -> 61 | K4: =IF(A4="","",COUNTIFS(ENERO!D:D,A4,ENERO!O:O,"DEVOLUCION")) -> 23 | L4: =IF(A4="","",COUNTIFS(ENERO!D:D,A4,ENERO!O:O,"PROCESO")) -> 0 | M4: =IF(A4="","",COUNTIFS(ENERO!D:D,A4,ENERO!O:O,"NOVEDAD")) -> 0 | N4: =IF(A4="","",COUNTIFS(ENERO!D:D,A4,ENERO!O:O,"PENDIENTE")) -> 6 | O4: =IF(A4="","",COUNTIFS(ENERO!D:D,A4,ENERO!O:O,"CANCELADO")) -> 12 | P4: =IF(A4="","",COUNTIFS(ENERO!D:D,A4,ENERO!O:O,"REVISAR")) -> 7
A5: =IFERROR(__xludf.DUMMYFUNCTION("""COMPUTED_VALUE"""),"FilmPro®") -> FilmPro® | B5: =IF(A5="","",SUMIF(ENERO!D:D, A5, ENERO!G:G)) -> 8355 | C5: =IF(A5="","",SUMIF(ENERO!D:D, A5, ENERO!E:E)) -> 1694.37 | D5: =IF(A5="","",SUMIF(ENERO!D:D, A5, ENERO!J:J)) -> 1972.23 | E5: =IF(A5="","",SUMIF(ENERO!D:D, A5, ENERO!L:L)) -> 683.79 | F5: =IFERROR(__xludf.DUMMYFUNCTION("IFERROR( IF(A5="""","""",SUM( FILTER( VALUE(SUBSTITUTE(TK!B:B,""."","","")), REGEXMATCH(TK!A:A,A5), MONTH( DATE( VALUE(RIGHT(LEFT(TK!A:A,10),4)), VALUE(MID(TK!A:A,4,2)), VALUE(LEFT(TK!A:A,2)) ) )=1 ) )), """") "),127.08) -> 127.08 | G5: =IFERROR(__xludf.DUMMYFUNCTION("IF( A5="""", """", SUM( FILTER( VALUE(SUBSTITUTE(FB!D:D, ""."", "","")), REGEXMATCH(FB!B:B, A5), MONTH(FB!E:E)=1 ) ) * 1.2 ) "),1875.828) -> 1875.828 | I5: =IF(A5="","",B5-SUM(C5:G5)) -> 2001.702 | J5: =IF(A5="","",COUNTIFS(ENERO!D:D,A5,ENERO!O:O,"ENTREGADO")) -> 329 | K5: =IF(A5="","",COUNTIFS(ENERO!D:D,A5,ENERO!O:O,"DEVOLUCION")) -> 133 | L5: =IF(A5="","",COUNTIFS(ENERO!D:D,A5,ENERO!O:O,"PROCESO")) -> 0 | M5: =IF(A5="","",COUNTIFS(ENERO!D:D,A5,ENERO!O:O,"NOVEDAD")) -> 0 | N5: =IF(A5="","",COUNTIFS(ENERO!D:D,A5,ENERO!O:O,"PENDIENTE")) -> 107 | O5: =IF(A5="","",COUNTIFS(ENERO!D:D,A5,ENERO!O:O,"CANCELADO")) -> 48 | P5: =IF(A5="","",COUNTIFS(ENERO!D:D,A5,ENERO!O:O,"REVISAR")) -> 0
A6: =IFERROR(__xludf.DUMMYFUNCTION("""COMPUTED_VALUE"""),"FLORA FRESH PRO™") -> FLORA FRESH PRO™ | B6: =IF(A6="","",SUMIF(ENERO!D:D, A6, ENERO!G:G)) -> 194 | C6: =IF(A6="","",SUMIF(ENERO!D:D, A6, ENERO!E:E)) -> 55 | D6: =IF(A6="","",SUMIF(ENERO!D:D, A6, ENERO!J:J)) -> 42.79 | E6: =IF(A6="","",SUMIF(ENERO!D:D, A6, ENERO!L:L)) -> 34.17 | F6: =IFERROR(__xludf.DUMMYFUNCTION("IFERROR( IF(A6="""","""",SUM( FILTER( VALUE(SUBSTITUTE(TK!B:B,""."","","")), REGEXMATCH(TK!A:A,A6), MONTH( DATE( VALUE(RIGHT(LEFT(TK!A:A,10),4)), VALUE(MID(TK!A:A,4,2)), VALUE(LEFT(TK!A:A,2)) ) )=1 ) )), """") "),"") | G6: =IFERROR(__xludf.DUMMYFUNCTION("IF( A6="""", """", SUM( FILTER( VALUE(SUBSTITUTE(FB!D:D, ""."", "","")), REGEXMATCH(FB!B:B, A6), MONTH(FB!E:E)=1 ) ) * 1.2 ) "),87.432) -> 87.432 | I6: =IF(A6="","",B6-SUM(C6:G6)) -> -25.392 | J6: =IF(A6="","",COUNTIFS(ENERO!D:D,A6,ENERO!O:O,"ENTREGADO")) -> 7 | K6: =IF(A6="","",COUNTIFS(ENERO!D:D,A6,ENERO!O:O,"DEVOLUCION")) -> 7 | L6: =IF(A6="","",COUNTIFS(ENERO!D:D,A6,ENERO!O:O,"PROCESO")) -> 0 | M6: =IF(A6="","",COUNTIFS(ENERO!D:D,A6,ENERO!O:O,"NOVEDAD")) -> 0 | N6: =IF(A6="","",COUNTIFS(ENERO!D:D,A6,ENERO!O:O,"PENDIENTE")) -> 0 | O6: =IF(A6="","",COUNTIFS(ENERO!D:D,A6,ENERO!O:O,"CANCELADO")) -> 3 | P6: =IF(A6="","",COUNTIFS(ENERO!D:D,A6,ENERO!O:O,"REVISAR")) -> 0
A7: =IFERROR(__xludf.DUMMYFUNCTION("""COMPUTED_VALUE"""),"Cuchillo Tazaki™") -> Cuchillo Tazaki™ | B7: =IF(A7="","",SUMIF(ENERO!D:D, A7, ENERO!G:G)) -> 4104.9 | C7: =IF(A7="","",SUMIF(ENERO!D:D, A7, ENERO!E:E)) -> 1086.4 | D7: =IF(A7="","",SUMIF(ENERO!D:D, A7, ENERO!J:J)) -> 1017.41 | E7: =IF(A7="","",SUMIF(ENERO!D:D, A7, ENERO!L:L)) -> 343.16 | F7: =IFERROR(__xludf.DUMMYFUNCTION("IFERROR( IF(A7="""","""",SUM( FILTER( VALUE(SUBSTITUTE(TK!B:B,""."","","")), REGEXMATCH(TK!A:A,A7), MONTH( DATE( VALUE(RIGHT(LEFT(TK!A:A,10),4)), VALUE(MID(TK!A:A,4,2)), VALUE(LEFT(TK!A:A,2)) ) )=1 ) )), """") "),"") | G7: =IFERROR(__xludf.DUMMYFUNCTION("IF( A7="""", """", SUM( FILTER( VALUE(SUBSTITUTE(FB!D:D, ""."", "","")), REGEXMATCH(FB!B:B, A7), MONTH(FB!E:E)=1 ) ) * 1.2 ) "),909.0) -> 909 | I7: =IF(A7="","",B7-SUM(C7:G7)) -> 748.93 | J7: =IF(A7="","",COUNTIFS(ENERO!D:D,A7,ENERO!O:O,"ENTREGADO")) -> 168 | K7: =IF(A7="","",COUNTIFS(ENERO!D:D,A7,ENERO!O:O,"DEVOLUCION")) -> 66 | L7: =IF(A7="","",COUNTIFS(ENERO!D:D,A7,ENERO!O:O,"PROCESO")) -> 0 | M7: =IF(A7="","",COUNTIFS(ENERO!D:D,A7,ENERO!O:O,"NOVEDAD")) -> 0 | N7: =IF(A7="","",COUNTIFS(ENERO!D:D,A7,ENERO!O:O,"PENDIENTE")) -> 37 | O7: =IF(A7="","",COUNTIFS(ENERO!D:D,A7,ENERO!O:O,"CANCELADO")) -> 16 | P7: =IF(A7="","",COUNTIFS(ENERO!D:D,A7,ENERO!O:O,"REVISAR")) -> 6
A8: =IFERROR(__xludf.DUMMYFUNCTION("""COMPUTED_VALUE"""),"FURBLADE™") -> FURBLADE™ | B8: =IF(A8="","",SUMIF(ENERO!D:D, A8, ENERO!G:G)) -> 39.99 | C8: =IF(A8="","",SUMIF(ENERO!D:D, A8, ENERO!E:E)) -> 7 | D8: =IF(A8="","",SUMIF(ENERO!D:D, A8, ENERO!J:J)) -> 9.9 | E8: =IF(A8="","",SUMIF(ENERO!D:D, A8, ENERO!L:L)) -> 0 | F8: =IFERROR(__xludf.DUMMYFUNCTION("IFERROR( IF(A8="""","""",SUM( FILTER( VALUE(SUBSTITUTE(TK!B:B,""."","","")), REGEXMATCH(TK!A:A,A8), MONTH( DATE( VALUE(RIGHT(LEFT(TK!A:A,10),4)), VALUE(MID(TK!A:A,4,2)), VALUE(LEFT(TK!A:A,2)) ) )=1 ) )), """") "),27.01) -> 27.01 | G8: =IFERROR(__xludf.DUMMYFUNCTION("IF( A8="""", """", SUM( FILTER( VALUE(SUBSTITUTE(FB!D:D, ""."", "","")), REGEXMATCH(FB!B:B, A8), MONTH(FB!E:E)=1 ) ) * 1.2 ) "),16.284) -> 16.284 | I8: =IF(A8="","",B8-SUM(C8:G8)) -> -20.204 | J8: =IF(A8="","",COUNTIFS(ENERO!D:D,A8,ENERO!O:O,"ENTREGADO")) -> 2 | K8: =IF(A8="","",COUNTIFS(ENERO!D:D,A8,ENERO!O:O,"DEVOLUCION")) -> 0 | L8: =IF(A8="","",COUNTIFS(ENERO!D:D,A8,ENERO!O:O,"PROCESO")) -> 0 | M8: =IF(A8="","",COUNTIFS(ENERO!D:D,A8,ENERO!O:O,"NOVEDAD")) -> 0 | N8: =IF(A8="","",COUNTIFS(ENERO!D:D,A8,ENERO!O:O,"PENDIENTE")) -> 2 | O8: =IF(A8="","",COUNTIFS(ENERO!D:D,A8,ENERO!O:O,"CANCELADO")) -> 0 | P8: =IF(A8="","",COUNTIFS(ENERO!D:D,A8,ENERO!O:O,"REVISAR")) -> 0
A9: =IFERROR(__xludf.DUMMYFUNCTION("""COMPUTED_VALUE"""),"REVISAR") -> REVISAR | B9: =IF(A9="","",SUMIF(ENERO!D:D, A9, ENERO!G:G)) -> 0 | D9: =IF(A9="","",SUMIF(ENERO!D:D, A9, ENERO!J:J)) -> 0 | I9: =IF(A9="","",B9-SUM(C9:G9)) -> 0 | J9: =IF(A9="","",COUNTIFS(ENERO!D:D,A9,ENERO!O:O,"ENTREGADO")) -> 0 | L9: =IF(A9="","",COUNTIFS(ENERO!D:D,A9,ENERO!O:O,"PROCESO")) -> 0 | M9: =IF(A9="","",COUNTIFS(ENERO!D:D,A9,ENERO!O:O,"NOVEDAD")) -> 0 | N9: =IF(A9="","",COUNTIFS(ENERO!D:D,A9,ENERO!O:O,"PENDIENTE")) -> 0 | O9: =IF(A9="","",COUNTIFS(ENERO!D:D,A9,ENERO!O:O,"CANCELADO")) -> 0 | P9: =IF(A9="","",COUNTIFS(ENERO!D:D,A9,ENERO!O:O,"REVISAR")) -> 15
A10: TOTAL | B10: =SUM(B4:B9) -> 14213.64 | C10: =SUM(C4:C9) -> 3327.77 | D10: =SUM(D4:D9) -> 3387.66 | E10: =SUM(E4:E9) -> 1176.57 | F10: =SUM(F4:F9) -> 154.09 | G10: =SUM(G4:G9) -> 3414.108 | H10: =SUM(H4:H9) -> 0 | I10: =SUM(I4:I9) -> 2753.442 | ... P10: =SUM(P4:P9) -> 28
A11: FEBRERO
A13: PRODUCTO | B13: VENTAS | C13: PROVEEDOR | D13: LOGISTICA | E13: DEVOLUCION | F13: TIK TOK ADS | G13: FACEBOOK ADS | H13: M PRIMA | I13: UTILIDAD | J13: =IFERROR( IF( SUM($J20:P20)=0, "", "ENTREGAS "&TEXT(J20/SUM($J20:P20), "0%") ), "" ) -> ENTREGAS 53% | K13: =IFERROR( IF( SUM($J20:P20)=0, "", "DEVOLUCION "&TEXT(K20/SUM($J20:P20), "0%") ), "" ) -> DEVOLUCION 17% | L13: =IFERROR( IF( SUM($J20:P20)=0, "", "PROCESO "&TEXT(L20/SUM($J20:P20), "0%") ), "" ) -> PROCESO 0% | M13: =IFERROR( IF( SUM($J20:P20)=0, "", "NOVEDAD "&TEXT(M20/SUM($J20:P20), "0%") ), "" ) -> NOVEDAD 0% | N13: =IFERROR( IF( SUM($J20:P20)=0, "", "PENDIENTES "&TEXT(N20/SUM($J20:P20), "0%") ), "" ) -> PENDIENTES 23% | O13: =IFERROR( IF( SUM($J20:P20)=0, "", "CANCELADOS "&TEXT(O20/SUM($J20:P20), "0%") ), "" ) -> CANCELADOS 6% | P13: =IFERROR( IF( SUM($J20:P20)=0, "", "REVISAR "&TEXT(P20/SUM($J20:P20), "0%") ), "" ) -> REVISAR 2%
A14: =IFERROR(__xludf.DUMMYFUNCTION("UNIQUE( FILTER( TRIM( FLATTEN( SPLIT(FEBRERO!D12:D1000, "";"") ) ), FLATTEN( SPLIT(FEBRERO!D12:D1000, "";"") )<>"""" ) )"),"Llave Multifuncional 360™") -> Llave Multifuncional 360™ | B14: =IF(A14="","",SUMIF(FEBRERO!D:D, A14, FEBRERO!G:G)) -> 431.86 | C14: =IF(A14="","",SUMIF(FEBRERO!D:D, A14, FEBRERO!E:E)) -> 114 | D14: =IF(A14="","",SUMIF(FEBRERO!D:D, A14, FEBRERO!J:J)) -> 119.29 | E14: =IF(A14="","",SUMIF(FEBRERO!D:D, A14, FEBRERO!L:L)) -> 53.61 | F14: =IFERROR(__xludf.DUMMYFUNCTION("IFERROR( IF(A14="""","""",SUM( FILTER( VALUE(SUBSTITUTE(TK!B:B,""."","","")), REGEXMATCH(TK!A:A,A14), MONTH( DATE( VALUE(RIGHT(LEFT(TK!A:A,10),4)), VALUE(MID(TK!A:A,4,2)), VALUE(LEFT(TK!A:A,2)) ) )=2 ) )), """") "),"") | G14: =IFERROR(__xludf.DUMMYFUNCTION("IF( A4="""", """", SUM( FILTER( VALUE(SUBSTITUTE(FB!D:D, ""."", "","")), REGEXMATCH(FB!B:B, A14), MONTH(FB!E:E)=2 ) ) * 1.2 ) "),190.66799999999998) -> 190.668 | I14: =IF(A14="","",B14-SUM(C14:G14)) -> -45.708 | J14: =IF(A14="","",COUNTIFS(FEBRERO!D:D,A14,FEBRERO!O:O,"ENTREGADO")) -> 20 | K14: =IF(A14="","",COUNTIFS(FEBRERO!D:D,A14,FEBRERO!O:O,"DEVOLUCION")) -> 11 | L14: =IF(A14="","",COUNTIFS(FEBRERO!D:D,A14,FEBRERO!O:O,"PROCESO")) -> 0 | M14: =IF(A14="","",COUNTIFS(FEBRERO!D:D,A14,FEBRERO!O:O,"NOVEDAD")) -> 0 | N14: =IF(A14="","",COUNTIFS(FEBRERO!D:D,A14,FEBRERO!O:O,"PENDIENTE")) -> 7 | O14: =IF(A14="","",COUNTIFS(FEBRERO!D:D,A14,FEBRERO!O:O,"CANCELADO")) -> 1 | P14: =IF(A14="","",COUNTIFS(FEBRERO!D:D,A14,FEBRERO!O:O,"REVISAR")) -> 0
A15: =IFERROR(__xludf.DUMMYFUNCTION("""COMPUTED_VALUE"""),"Cuchillo Tazaki™") -> Cuchillo Tazaki™ | B15: =IF(A15="","",SUMIF(FEBRERO!D:D, A15, FEBRERO!G:G)) -> 3869.68 | C15: =IF(A15="","",SUMIF(FEBRERO!D:D, A15, FEBRERO!E:E)) -> 1214.4 | D15: =IF(A15="","",SUMIF(FEBRERO!D:D, A15, FEBRERO!J:J)) -> 938.37 | E15: =IF(A15="","",SUMIF(FEBRERO!D:D, A15, FEBRERO!L:L)) -> 145.53 | F15: =IFERROR(__xludf.DUMMYFUNCTION("IFERROR( IF(A15="""","""",SUM( FILTER( VALUE(SUBSTITUTE(TK!B:B,""."","","")), REGEXMATCH(TK!A:A,A15), MONTH( DATE( VALUE(RIGHT(LEFT(TK!A:A,10),4)), VALUE(MID(TK!A:A,4,2)), VALUE(LEFT(TK!A:A,2)) ) )=2 ) )), """") "),"") | G15: =IFERROR(__xludf.DUMMYFUNCTION("IF( A5="""", """", SUM( FILTER( VALUE(SUBSTITUTE(FB!D:D, ""."", "","")), REGEXMATCH(FB!B:B, A15), MONTH(FB!E:E)=2 ) ) * 1.2 ) "),1425.2160000000001) -> 1425.216 | I15: =IF(A15="","",B15-SUM(C15:G15)) -> 146.164 | J15: =IF(A15="","",COUNTIFS(FEBRERO!D:D,A15,FEBRERO!O:O,"ENTREGADO")) -> 159 | K15: =IF(A15="","",COUNTIFS(FEBRERO!D:D,A15,FEBRERO!O:O,"DEVOLUCION")) -> 57 | L15: =IF(A15="","",COUNTIFS(FEBRERO!D:D,A15,FEBRERO!O:O,"PROCESO")) -> 0 | M15: =IF(A15="","",COUNTIFS(FEBRERO!D:D,A15,FEBRERO!O:O,"NOVEDAD")) -> 0 | N15: =IF(A15="","",COUNTIFS(FEBRERO!D:D,A15,FEBRERO!O:O,"PENDIENTE")) -> 79 | O15: =IF(A15="","",COUNTIFS(FEBRERO!D:D,A15,FEBRERO!O:O,"CANCELADO")) -> 17 | P15: =IF(A15="","",COUNTIFS(FEBRERO!D:D,A15,FEBRERO!O:O,"REVISAR")) -> 1
A16: =IFERROR(__xludf.DUMMYFUNCTION("""COMPUTED_VALUE"""),"FilmPro®") -> FilmPro® | B16: =IF(A16="","",SUMIF(FEBRERO!D:D, A16, FEBRERO!G:G)) -> 4990 | C16: =IF(A16="","",SUMIF(FEBRERO!D:D, A16, FEBRERO!E:E)) -> 952.7 | D16: =IF(A16="","",SUMIF(FEBRERO!D:D, A16, FEBRERO!J:J)) -> 1132.38 | E16: =IF(A16="","",SUMIF(FEBRERO!D:D, A16, FEBRERO!L:L)) -> 116.18 | F16: =IFERROR(__xludf.DUMMYFUNCTION("IFERROR( IF(A16="""","""",SUM( FILTER( VALUE(SUBSTITUTE(TK!B:B,""."","","")), REGEXMATCH(TK!A:A,A16), MONTH( DATE( VALUE(RIGHT(LEFT(TK!A:A,10),4)), VALUE(MID(TK!A:A,4,2)), VALUE(LEFT(TK!A:A,2)) ) )=2 ) )), """") "),300.71) -> 300.71 | G16: =IFERROR(__xludf.DUMMYFUNCTION("IF( A6="""", """", SUM( FILTER( VALUE(SUBSTITUTE(FB!D:D, ""."", "","")), REGEXMATCH(FB!B:B, A16), MONTH(FB!E:E)=2 ) ) * 1.2 ) "),1246.488) -> 1246.488 | I16: =IF(A16="","",B16-SUM(C16:G16)) -> 1241.542 | J16: =IF(A16="","",COUNTIFS(FEBRERO!D:D,A16,FEBRERO!O:O,"ENTREGADO")) -> 197 | K16: =IF(A16="","",COUNTIFS(FEBRERO!D:D,A16,FEBRERO!O:O,"DEVOLUCION")) -> 52 | L16: =IF(A16="","",COUNTIFS(FEBRERO!D:D,A16,FEBRERO!O:O,"PROCESO")) -> 1 | M16: =IF(A16="","",COUNTIFS(FEBRERO!D:D,A16,FEBRERO!O:O,"NOVEDAD")) -> 1 | N16: =IF(A16="","",COUNTIFS(FEBRERO!D:D,A16,FEBRERO!O:O,"PENDIENTE")) -> 74 | O16: =IF(A16="","",COUNTIFS(FEBRERO!D:D,A16,FEBRERO!O:O,"CANCELADO")) -> 22 | P16: =IF(A16="","",COUNTIFS(FEBRERO!D:D,A16,FEBRERO!O:O,"REVISAR")) -> 1
A17: =IFERROR(__xludf.DUMMYFUNCTION("""COMPUTED_VALUE"""),"REVISAR") -> REVISAR | B17: =IF(A17="","",SUMIF(FEBRERO!D:D, A17, FEBRERO!G:G)) -> 0 | C17: =IF(A17="","",SUMIF(FEBRERO!D:D, A17, FEBRERO!E:E)) -> 0 | D17: =IF(A17="","",SUMIF(FEBRERO!D:D, A17, FEBRERO!J:J)) -> 0 | E17: =IF(A17="","",SUMIF(FEBRERO!D:D, A17, FEBRERO!L:L)) -> 0 | F17: =IFERROR(__xludf.DUMMYFUNCTION("IFERROR( IF(A17="""","""",SUM( FILTER( VALUE(SUBSTITUTE(TK!B:B,""."","","")), REGEXMATCH(TK!A:A,A17), MONTH( DATE( VALUE(RIGHT(LEFT(TK!A:A,10),4)), VALUE(MID(TK!A:A,4,2)), VALUE(LEFT(TK!A:A,2)) ) )=2 ) )), """") "),"") | I17: =IF(A17="","",B17-SUM(C17:G17)) -> 0 | J17: =IF(A17="","",COUNTIFS(FEBRERO!D:D,A17,FEBRERO!O:O,"ENTREGADO")) -> 0 | K17: =IF(A17="","",COUNTIFS(FEBRERO!D:D,A17,FEBRERO!O:O,"DEVOLUCION")) -> 0 | L17: =IF(A17="","",COUNTIFS(FEBRERO!D:D,A17,FEBRERO!O:O,"PROCESO")) -> 0 | M17: =IF(A17="","",COUNTIFS(FEBRERO!D:D,A17,FEBRERO!O:O,"NOVEDAD")) -> 0 | N17: =IF(A17="","",COUNTIFS(FEBRERO!D:D,A17,FEBRERO!O:O,"PENDIENTE")) -> 0 | O17: =IF(A17="","",COUNTIFS(FEBRERO!D:D,A17,FEBRERO!O:O,"CANCELADO")) -> 0 | P17: =IF(A17="","",COUNTIFS(FEBRERO!D:D,A17,FEBRERO!O:O,"REVISAR")) -> 12
A18: =IFERROR(__xludf.DUMMYFUNCTION("""COMPUTED_VALUE"""),"FreeBeat Adapter") -> FreeBeat Adapter | B18: =IF(A18="","",SUMIF(FEBRERO!D:D, A18, FEBRERO!G:G)) -> 152.92 | C18: =IF(A18="","",SUMIF(FEBRERO!D:D, A18, FEBRERO!E:E)) -> 70 | D18: =IF(A18="","",SUMIF(FEBRERO!D:D, A18, FEBRERO!J:J)) -> 37.85 | E18: =IF(A18="","",SUMIF(FEBRERO!D:D, A18, FEBRERO!L:L)) -> 0 | F18: =IFERROR(__xludf.DUMMYFUNCTION("IFERROR( IF(A18="""","""",SUM( FILTER( VALUE(SUBSTITUTE(TK!B:B,""."","","")), REGEXMATCH(TK!A:A,A18), MONTH( DATE( VALUE(RIGHT(LEFT(TK!A:A,10),4)), VALUE(MID(TK!A:A,4,2)), VALUE(LEFT(TK!A:A,2)) ) )=2 ) )), """") "),"") | G18: =IFERROR(__xludf.DUMMYFUNCTION("IF( A8="""", """", SUM( FILTER( VALUE(SUBSTITUTE(FB!D:D, ""."", "","")), REGEXMATCH(FB!B:B, A18), MONTH(FB!E:E)=2 ) ) * 1.2 ) "),29.483999999999998) -> 29.484 | I18: =IF(A18="","",B18-SUM(C18:G18)) -> 15.586 | J18: =IF(A18="","",COUNTIFS(FEBRERO!D:D,A18,FEBRERO!O:O,"ENTREGADO")) -> 6 | K18: =IF(A18="","",COUNTIFS(FEBRERO!D:D,A18,FEBRERO!O:O,"DEVOLUCION")) -> 1 | L18: =IF(A18="","",COUNTIFS(FEBRERO!D:D,A18,FEBRERO!O:O,"PROCESO")) -> 0 | M18: =IF(A18="","",COUNTIFS(FEBRERO!D:D,A18,FEBRERO!O:O,"NOVEDAD")) -> 0 | N18: =IF(A18="","",COUNTIFS(FEBRERO!D:D,A18,FEBRERO!O:O,"PENDIENTE")) -> 6 | O18: =IF(A18="","",COUNTIFS(FEBRERO!D:D,A18,FEBRERO!O:O,"CANCELADO")) -> 0 | P18: =IF(A18="","",COUNTIFS(FEBRERO!D:D,A18,FEBRERO!O:O,"REVISAR")) -> 0
A19: =IFERROR(__xludf.DUMMYFUNCTION("""COMPUTED_VALUE"""),"DrainGuard Pro™") -> DrainGuard Pro™ | B19: =IF(A19="","",SUMIF(FEBRERO!D:D, A19, FEBRERO!G:G)) -> 57.01 | C19: =IF(A19="","",SUMIF(FEBRERO!D:D, A19, FEBRERO!E:E)) -> 20 | D19: =IF(A19="","",SUMIF(FEBRERO!D:D, A19, FEBRERO!J:J)) -> 8.98 | E19: =IF(A19="","",SUMIF(FEBRERO!D:D, A19, FEBRERO!L:L)) -> 0 | F19: =IFERROR(__xludf.DUMMYFUNCTION("IFERROR( IF(A19="""","""",SUM( FILTER( VALUE(SUBSTITUTE(TK!B:B,""."","","")), REGEXMATCH(TK!A:A,A19), MONTH( DATE( VALUE(RIGHT(LEFT(TK!A:A,10),4)), VALUE(MID(TK!A:A,4,2)), VALUE(LEFT(TK!A:A,2)) ) )=2 ) )), """") "),"") | G19: =IFERROR(__xludf.DUMMYFUNCTION("IF( A9="""", """", SUM( FILTER( VALUE(SUBSTITUTE(FB!D:D, ""."", "","")), REGEXMATCH(FB!B:B, A19), MONTH(FB!E:E)=2 ) ) * 1.2 ) "),"#N/A") -> #N/A | I19: =IF(A19="","",B19-SUM(C19:G19)) -> #N/A | J19: =IF(A19="","",COUNTIFS(FEBRERO!D:D,A19,FEBRERO!O:O,"ENTREGADO")) -> 2 | K19: =IF(A19="","",COUNTIFS(FEBRERO!D:D,A19,FEBRERO!O:O,"DEVOLUCION")) -> 0 | L19: =IF(A19="","",COUNTIFS(FEBRERO!D:D,A19,FEBRERO!O:O,"PROCESO")) -> 0 | M19: =IF(A19="","",COUNTIFS(FEBRERO!D:D,A19,FEBRERO!O:O,"NOVEDAD")) -> 0 | N19: =IF(A19="","",COUNTIFS(FEBRERO!D:D,A19,FEBRERO!O:O,"PENDIENTE")) -> 0 | O19: =IF(A19="","",COUNTIFS(FEBRERO!D:D,A19,FEBRERO!O:O,"CANCELADO")) -> 0 | P19: =IF(A19="","",COUNTIFS(FEBRERO!D:D,A19,FEBRERO!O:O,"REVISAR")) -> 0
A20: TOTAL | B20: =SUM(B14:B19) -> 9501.47 | C20: =SUM(C14:C19) -> 2371.1 | D20: =SUM(D14:D19) -> 2236.87 | E20: =SUM(E14:E19) -> 315.32 | F20: =SUM(F14:F19) -> 300.71 | G20: =SUM(G14:G19) -> #N/A | H20: =SUM(H14:H19) -> 0 | I20: =SUM(I14:I19) -> #N/A | ... P20: =SUM(P14:P19) -> 14
A21: MARZO
A23: PRODUCTO | B23: VENTAS | C23: PROVEEDOR | D23: LOGISTICA | E23: DEVOLUCION | F23: TIK TOK ADS | G23: FACEBOOK ADS | H23: M PRIMA | I23: UTILIDAD | J23: =IFERROR( IF( SUM($J30:P30)=0, "", "ENTREGAS "&TEXT(J30/SUM($J30:P30), "0%") ), "" ) -> ENTREGAS 49% | K23: =IFERROR( IF( SUM($J30:P30)=0, "", "DEVOLUCION "&TEXT(K30/SUM($J30:P30), "0%") ), "" ) -> DEVOLUCION 8% | L23: =IFERROR( IF( SUM($J30:P30)=0, "", "PROCESO "&TEXT(L30/SUM($J30:P30), "0%") ), "" ) -> PROCESO 8% | M23: =IFERROR( IF( SUM($J30:P30)=0, "", "NOVEDAD "&TEXT(M30/SUM($J30:P30), "0%") ), "" ) -> NOVEDAD 5% | N23: =IFERROR( IF( SUM($J30:P30)=0, "", "PENDIENTES "&TEXT(N30/SUM($J30:P30), "0%") ), "" ) -> PENDIENTES 24% | O23: =IFERROR( IF( SUM($J30:P30)=0, "", "CANCELADOS "&TEXT(O30/SUM($J30:P30), "0%") ), "" ) -> CANCELADOS 5% | P23: =IFERROR( IF( SUM($J30:P30)=0, "", "REVISAR "&TEXT(P30/SUM($J30:P30), "0%") ), "" ) -> REVISAR 1%
A24: =IFERROR(__xludf.DUMMYFUNCTION("UNIQUE( FILTER( TRIM( FLATTEN( SPLIT(MARZO!D22:D1000, "";"") ) ), FLATTEN( SPLIT(MARZO!D22:D1000, "";"") )<>"""" ) )"),"FilmPro®") -> FilmPro® | B24: =IF(A24="","",SUMIF(MARZO!D:D, A24, MARZO!G:G)) -> 3424.94 | C24: =IF(A24="","",SUMIF(MARZO!D:D, A24, MARZO!E:E)) -> 683.82 | D24: =IF(A24="","",SUMIF(MARZO!D:D, A24, MARZO!J:J)) -> 795.02 | E24: =IF(A24="","",SUMIF(MARZO!D:D, A24, MARZO!L:L)) -> 0 | F24: =IFERROR(__xludf.DUMMYFUNCTION("IFERROR( IF(A24="""","""",SUM( FILTER( VALUE(SUBSTITUTE(TK!B:B,""."","","")), REGEXMATCH(TK!A:A,A24), MONTH( DATE( VALUE(RIGHT(LEFT(TK!A:A,10),4)), VALUE(MID(TK!A:A,4,2)), VALUE(LEFT(TK!A:A,2)) ) )=3 ) )), """") "),"") | I24: =IF(A24="","",B24-SUM(C24:G24)) -> 1946.1 | J24: =IF(A24="","",COUNTIFS(MARZO!D:D,A24,MARZO!O:O,"ENTREGADO")) -> 135 | K24: =IF(A24="","",COUNTIFS(MARZO!D:D,A24,MARZO!O:O,"DEVOLUCION")) -> 24 | L24: =IF(A24="","",COUNTIFS(MARZO!D:D,A24,MARZO!O:O,"PROCESO")) -> 24 | M24: =IF(A24="","",COUNTIFS(MARZO!D:D,A24,MARZO!O:O,"NOVEDAD")) -> 12 | N24: =IF(A24="","",COUNTIFS(MARZO!D:D,A24,MARZO!O:O,"PENDIENTE")) -> 52 | O24: =IF(A24="","",COUNTIFS(MARZO!D:D,A24,MARZO!O:O,"CANCELADO")) -> 15 | P24: =IF(A24="","",COUNTIFS(MARZO!D:D,A24,MARZO!O:O,"REVISAR")) -> 1
A25: =IFERROR(__xludf.DUMMYFUNCTION("""COMPUTED_VALUE"""),"Cuchillo Tazaki™") -> Cuchillo Tazaki™ | B25: =IF(A25="","",SUMIF(MARZO!D:D, A25, MARZO!G:G)) -> 465 | C25: =IF(A25="","",SUMIF(MARZO!D:D, A25, MARZO!E:E)) -> 152.55 | D25: =IF(A25="","",SUMIF(MARZO!D:D, A25, MARZO!J:J)) -> 116.31 | E25: =IF(A25="","",SUMIF(MARZO!D:D, A25, MARZO!L:L)) -> 0 | F25: =IFERROR(__xludf.DUMMYFUNCTION("IFERROR( IF(A25="""","""",SUM( FILTER( VALUE(SUBSTITUTE(TK!B:B,""."","","")), REGEXMATCH(TK!A:A,A25), MONTH( DATE( VALUE(RIGHT(LEFT(TK!A:A,10),4)), VALUE(MID(TK!A:A,4,2)), VALUE(LEFT(TK!A:A,2)) ) )=2 ) )), """") "),"") | I25: =IF(A25="","",B25-SUM(C25:G25)) -> 196.14 | J25: =IF(A25="","",COUNTIFS(MARZO!D:D,A25,MARZO!O:O,"ENTREGADO")) -> 20 | K25: =IF(A25="","",COUNTIFS(MARZO!D:D,A25,MARZO!O:O,"DEVOLUCION")) -> 1 | L25: =IF(A25="","",COUNTIFS(MARZO!D:D,A25,MARZO!O:O,"PROCESO")) -> 5 | M25: =IF(A25="","",COUNTIFS(MARZO!D:D,A25,MARZO!O:O,"NOVEDAD")) -> 7 | N25: =IF(A25="","",COUNTIFS(MARZO!D:D,A25,MARZO!O:O,"PENDIENTE")) -> 25 | O25: =IF(A25="","",COUNTIFS(MARZO!D:D,A25,MARZO!O:O,"CANCELADO")) -> 1 | P25: =IF(A25="","",COUNTIFS(MARZO!D:D,A25,MARZO!O:O,"REVISAR")) -> 0
A26: =IFERROR(__xludf.DUMMYFUNCTION("""COMPUTED_VALUE"""),"FreeBeat Adapter") -> FreeBeat Adapter | B26: =IF(A26="","",SUMIF(MARZO!D:D, A26, MARZO!G:G)) -> 276.78 | C26: =IF(A26="","",SUMIF(MARZO!D:D, A26, MARZO!E:E)) -> 130 | D26: =IF(A26="","",SUMIF(MARZO!D:D, A26, MARZO!J:J)) -> 66.33 | E26: =IF(A26="","",SUMIF(MARZO!D:D, A26, MARZO!L:L)) -> 0 | F26: =IFERROR(__xludf.DUMMYFUNCTION("IFERROR( IF(A26="""","""",SUM( FILTER( VALUE(SUBSTITUTE(TK!B:B,""."","","")), REGEXMATCH(TK!A:A,A26), MONTH( DATE( VALUE(RIGHT(LEFT(TK!A:A,10),4)), VALUE(MID(TK!A:A,4,2)), VALUE(LEFT(TK!A:A,2)) ) )=2 ) )), """") "),"") | I26: =IF(A26="","",B26-SUM(C26:G26)) -> 80.45 | J26: =IF(A26="","",COUNTIFS(MARZO!D:D,A26,MARZO!O:O,"ENTREGADO")) -> 11 | K26: =IF(A26="","",COUNTIFS(MARZO!D:D,A26,MARZO!O:O,"DEVOLUCION")) -> 2 | L26: =IF(A26="","",COUNTIFS(MARZO!D:D,A26,MARZO!O:O,"PROCESO")) -> 0 | M26: =IF(A26="","",COUNTIFS(MARZO!D:D,A26,MARZO!O:O,"NOVEDAD")) -> 0 | N26: =IF(A26="","",COUNTIFS(MARZO!D:D,A26,MARZO!O:O,"PENDIENTE")) -> 9 | O26: =IF(A26="","",COUNTIFS(MARZO!D:D,A26,MARZO!O:O,"CANCELADO")) -> 0 | P26: =IF(A26="","",COUNTIFS(MARZO!D:D,A26,MARZO!O:O,"REVISAR")) -> 1
A27: =IFERROR(__xludf.DUMMYFUNCTION("""COMPUTED_VALUE"""),"DrainGuard Pro™") -> DrainGuard Pro™ | B27: =IF(A27="","",SUMIF(MARZO!D:D, A27, MARZO!G:G)) -> 510.05 | C27: =IF(A27="","",SUMIF(MARZO!D:D, A27, MARZO!E:E)) -> 156.5 | D27: =IF(A27="","",SUMIF(MARZO!D:D, A27, MARZO!J:J)) -> 108.68 | E27: =IF(A27="","",SUMIF(MARZO!D:D, A27, MARZO!L:L)) -> 0 | F27: =IFERROR(__xludf.DUMMYFUNCTION("IFERROR( IF(A27="""","""",SUM( FILTER( VALUE(SUBSTITUTE(TK!B:B,""."","","")), REGEXMATCH(TK!A:A,A27), MONTH( DATE( VALUE(RIGHT(LEFT(TK!A:A,10),4)), VALUE(MID(TK!A:A,4,2)), VALUE(LEFT(TK!A:A,2)) ) )=2 ) )), """") "),"") | I27: =IF(A27="","",B27-SUM(C27:G27)) -> 244.87 | J27: =IF(A27="","",COUNTIFS(MARZO!D:D,A27,MARZO!O:O,"ENTREGADO")) -> 19 | K27: =IF(A27="","",COUNTIFS(MARZO!D:D,A27,MARZO!O:O,"DEVOLUCION")) -> 4 | L27: =IF(A27="","",COUNTIFS(MARZO!D:D,A27,MARZO!O:O,"PROCESO")) -> 0 | M27: =IF(A27="","",COUNTIFS(MARZO!D:D,A27,MARZO!O:O,"NOVEDAD")) -> 0 | N27: =IF(A27="","",COUNTIFS(MARZO!D:D,A27,MARZO!O:O,"PENDIENTE")) -> 5 | O27: =IF(A27="","",COUNTIFS(MARZO!D:D,A27,MARZO!O:O,"CANCELADO")) -> 4 | P27: =IF(A27="","",COUNTIFS(MARZO!D:D,A27,MARZO!O:O,"REVISAR")) -> 0
A28: =IFERROR(__xludf.DUMMYFUNCTION("""COMPUTED_VALUE"""),"JBL GO 4") -> JBL GO 4 | B28: =IF(A28="","",SUMIF(FEBRERO!D:D, A28, FEBRERO!G:G)) -> 0 | C28: =IF(A28="","",SUMIF(MARZO!D:D, A28, MARZO!E:E)) -> 0 | D28: =IF(A28="","",SUMIF(MARZO!D:D, A28, MARZO!J:J)) -> 0 | E28: =IF(A28="","",SUMIF(MARZO!D:D, A28, MARZO!L:L)) -> 0 | F28: =IFERROR(__xludf.DUMMYFUNCTION("IFERROR( IF(A28="""","""",SUM( FILTER( VALUE(SUBSTITUTE(TK!B:B,""."","","")), REGEXMATCH(TK!A:A,A28), MONTH( DATE( VALUE(RIGHT(LEFT(TK!A:A,10),4)), VALUE(MID(TK!A:A,4,2)), VALUE(LEFT(TK!A:A,2)) ) )=2 ) )), """") "),"") | I28: =IF(A28="","",B28-SUM(C28:G28)) -> 0 | J28: =IF(A28="","",COUNTIFS(MARZO!D:D,A28,MARZO!O:O,"ENTREGADO")) -> 0 | K28: =IF(A28="","",COUNTIFS(MARZO!D:D,A28,MARZO!O:O,"DEVOLUCION")) -> 1 | L28: =IF(A28="","",COUNTIFS(MARZO!D:D,A28,MARZO!O:O,"PROCESO")) -> 0 | M28: =IF(A28="","",COUNTIFS(MARZO!D:D,A28,MARZO!O:O,"NOVEDAD")) -> 0 | N28: =IF(A28="","",COUNTIFS(MARZO!D:D,A28,MARZO!O:O,"PENDIENTE")) -> 0 | O28: =IF(A28="","",COUNTIFS(MARZO!D:D,A28,MARZO!O:O,"CANCELADO")) -> 0 | P28: =IF(A28="","",COUNTIFS(FEBRERO!D:D,A28,FEBRERO!O:O,"REVISAR")) -> 0
B29: =IF(A29="","",SUMIF(FEBRERO!D:D, A29, FEBRERO!G:G)) | C29: =IF(A29="","",SUMIF(FEBRERO!D:D, A29, FEBRERO!E:E)) | D29: =IF(A29="","",SUMIF(MARZO!D:D, A29, MARZO!J:J)) | E29: =IF(A29="","",SUMIF(FEBRERO!D:D, A29, FEBRERO!L:L)) | F29: =IFERROR(__xludf.DUMMYFUNCTION("IFERROR( IF(A29="""","""",SUM( FILTER( VALUE(SUBSTITUTE(TK!B:B,""."","","")), REGEXMATCH(TK!A:A,A29), MONTH( DATE( VALUE(RIGHT(LEFT(TK!A:A,10),4)), VALUE(MID(TK!A:A,4,2)), VALUE(LEFT(TK!A:A,2)) ) )=2 ) )), """") "),"") | I29: =IF(A29="","",B29-SUM(C29:G29)) | J29: =IF(A29="","",COUNTIFS(MARZO!D:D,A29,MARZO!O:O,"ENTREGADO")) | K29: =IF(A29="","",COUNTIFS(FEBRERO!D:D,A29,FEBRERO!O:O,"DEVOLUCION")) | L29: =IF(A29="","",COUNTIFS(FEBRERO!D:D,A29,FEBRERO!O:O,"PROCESO")) | M29: =IF(A29="","",COUNTIFS(FEBRERO!D:D,A29,FEBRERO!O:O,"NOVEDAD")) | N29: =IF(A29="","",COUNTIFS(FEBRERO!D:D,A29,FEBRERO!O:O,"PENDIENTE")) | O29: =IF(A29="","",COUNTIFS(FEBRERO!D:D,A29,FEBRERO!O:O,"CANCELADO")) | P29: =IF(A29="","",COUNTIFS(FEBRERO!D:D,A29,FEBRERO!O:O,"REVISAR"))
A30: TOTAL | B30: =SUM(B24:B29) -> 4676.77 | C30: =SUM(C24:C29) -> 1122.87 | D30: =SUM(D24:D29) -> 1086.34 | E30: =SUM(E24:E29) -> 0 | F30: =SUM(F24:F29) -> 0 | G30: =SUM(G24:G29) -> 0 | H30: =SUM(H24:H29) -> 0 | I30: =SUM(I24:I29) -> 2467.56 | ... P30: =SUM(P24:P29) -> 2

Sheet TK
A1: Nombre de la campaña | B1: Coste | C1: Moneda
A2: 22/01/2026 - FilmPro® - ABO | B2: 127.08 | C2: USD
A3: 23/01/2025 - FURBLADE™ - ABO | B3: 46049 | C3: USD
A4: 25/01/2025 - Llave Multifuncional 360™ - ABO | B4: 0 | C4: USD
A5: Total: 3 resultados | B5: 154.09 | C5: USD
K6: 10/01 DUPLICADO 09/11/2025-Cuchillo Tazaki™- ABO - 16/11/2025 | L6: 17/01/2026 - FilmPro® - CBO | M6: 27/12/2025 / DUPLICADO CBO / 22/12/2025 /Llave Multifuncional 360™/ ABO | N6: 06/01/2026- FilmPro® - ABO | O6: 25/01/2026- Llave Multifuncional 360™-CBO | P6: 04/01/2026- FLORA FRESH PRO™- ABO | Q6: 27/01/2026 - FURBLADE™ -ABO | R6: JBL / 20-01 / WHATSAPP | S6: 06/01/2026- FLORA FRESH PRO™- ESCALADO -CBO
A7: FEBRERO | J7: 0 | K7: 0 | L7: 0 | M7: 0 | N7: 0 | O7: 0 | P7: 0 | Q7: 0 | R7: 0 | S7: 0
A8: 23/02/2026- FilmPro® - ABO | B8: 54.26 | J8: 0 | K8: 0 | L8: 0 | M8: 0 | N8: 0 | O8: 0 | P8: 0 | Q8: 0 | R8: 0 | S8: 0
A9: 22/02/2026 - FilmPro® - ABO - | B9: 51.54 | J9: 0 | K9: 0 | L9: 0 | M9: 0 | N9: 0 | O9: 0 | P9: 0 | Q9: 0 | R9: 0 | S9: 0
A10: 18/02/2026 - FilmPro® - ABO - | B10: 46.05 | J10: 0 | K10: 0 | L10: 0 | M10: 0 | N10: 0 | O10: 0 | P10: 20.64 | Q10: 0 | R10: 0 | S10: 0
A11: 21/02/2026 - FilmPro® - ABO - | B11: 40.27 | J11: 0 | K11: 0 | L11: 0 | M11: 41.55 | N11: 0 | O11: 0 | P11: 0 | Q11: 0 | R11: 0 | S11: 0
A12: 19/02/2026 - FilmPro® - ABO - | B12: 39.87 | J12: 0 | K12: 0 | L12: 0 | M12: 0 | N12: 0 | O12: 0 | P12: 17.81 | Q12: 0 | R12: 0 | S12: 0
A13: 17/02/2026- FilmPro® - ABO - | B13: 36.39 | J13: 0 | K13: 0 | L13: 0 | M13: 54.25 | N13: 0 | O13: 0 | P13: 0 | Q13: 0 | R13: 0 | S13: 0
A14: 20/02/2026 - FilmPro® - ABO - | B14: 32.33 | J14: 0 | K14: 0 | L14: 0 | M14: 0 | N14: 0 | O14: 0 | P14: 9.33 | Q14: 0 | R14: 0 | S14: 0
J15: 0 | K15: 0 | L15: 0 | M15: 0 | N15: 17.96 | O15: 0 | P15: 0 | Q15: 0 | R15: 0 | S15: 0
J16: 0 | K16: 0 | L16: 0 | M16: 0 | N16: 0 | O16: 0 | P16: 0 | Q16: 0 | R16: 0 | S16: 6.28
J17: 0 | K17: 0 | L17: 0 | M17: 51.74 | N17: 0 | O17: 0 | P17: 0 | Q17: 0 | R17: 0 | S17: 0
J18: 0 | K18: 0 | L18: 0 | M18: 0 | N18: 0 | O18: 0 | P18: 5.89 | Q18: 0 | R18: 0 | S18: 0
J19: 0 | K19: 0 | L19: 0 | M19: 0 | N19: 19.44 | O19: 0 | P19: 0 | Q19: 0 | R19: 0 | S19: 0
J20: 0 | K20: 0 | L20: 0 | M20: 52.45 | N20: 0 | O20: 0 | P20: 0 | Q20: 0 | R20: 0 | S20: 0
J21: 0 | K21: 0 | L21: 0 | M21: 0 | N21: 0 | O21: 0 | P21: 5.96 | Q21: 0 | R21: 0 | S21: 0
J22: 0 | K22: 0 | L22: 0 | M22: 0 | N22: 17.63 | O22: 0 | P22: 0 | Q22: 0 | R22: 0 | S22: 0
J23: 0 | K23: 0 | L23: 0 | M23: 0 | N23: 0 | O23: 0 | P23: 4.72 | Q23: 0 | R23: 0 | S23: 0
J24: 0 | K24: 0 | L24: 0 | M24: 0 | N24: 15.94 | O24: 0 | P24: 0 | Q24: 0 | R24: 0 | S24: 0
J25: 0 | K25: 0 | L25: 0 | M25: 0 | N25: 0 | O25: 0 | P25: 2.23 | Q25: 0 | R25: 0 | S25: 0
J26: 0 | K26: 0 | L26: 0 | M26: 0 | N26: 11.26 | O26: 0 | P26: 0 | Q26: 0 | R26: 0 | S26: 0
... J65: 0 | K65: 0 | L65: 0 | M65: 0 | N65: 0 | O65: 0 | P65: 0 | Q65: 13.57 | R65: 0 | S65: 0

Sheet FB
A1: Nombre de la cuenta | B1: Nombre de la campaña | C1: Divisa | D1: Importe gastado (USD) | E1: Inicio del informe | F1: Fin del informe
C2: USD | D2: 2855.86 | E2: 46023 | F2: 46053
A3: 2 IMPORTEX MODA 2025 CTA PUBLICITARIA | B3: 10/01/ DUPLICADO / 06/01/ FilmPro® - CBO | C3: USD | D3: 853.59 | E3: 46023 | F3: 46053
A4: IMPORTEX MODA 2025 CTA PUBLICITARIA | B4: 10/01 DUPLICADO 09/11/2025-Cuchillo Tazaki™- ABO - 16/11/2025 | C4: USD | D4: 757.5 | E4: 46023 | F4: 46053
A5: IMPORTEX MODA 2025 CTA PUBLICITARIA | B5: 17/01/2026 - FilmPro® - CBO | C5: USD | D5: 539.77 | E5: 46023 | F5: 46053
A6: 2 IMPORTEX MODA 2025 CTA PUBLICITARIA | B6: 25/01/2026- Llave Multifuncional 360™-CBO | C6: USD | D6: 237.98 | E6: 46023 | F6: 46053
A7: IMPORTEX MODA 2025 CTA PUBLICITARIA | B7: 27/12/2025 / DUPLICADO CBO / 22/12/2025 /Llave Multifuncional 360™/ ABO | C7: USD | D7: 199.99 | E7: 46023 | F7: 46053
A8: 2 IMPORTEX MODA 2025 CTA PUBLICITARIA | B8: 06/01/2026- FilmPro® - ABO | C8: USD | D8: 169.83 | E8: 46023 | F8: 46053
A9: 2 IMPORTEX MODA 2025 CTA PUBLICITARIA | B9: 04/01/2026- FLORA FRESH PRO™- ABO | C9: USD | D9: 66.58 | E9: 46023 | F9: 46053
A10: IMPORTEX MODA 2025 CTA PUBLICITARIA | B10: 27/01/2026 - FURBLADE™ -ABO | C10: USD | D10: 13.57 | E10: 46023 | F10: 46053
A11: 3 IMPORTEX 2025 CTA PUBLICITARIA | B11: JBL / 20-01 / WHATSAPP | C11: USD | D11: 10.77 | E11: 46023 | F11: 46053
A12: 2 IMPORTEX MODA 2025 CTA PUBLICITARIA | B12: 06/01/2026- FLORA FRESH PRO™- ESCALADO -CBO | C12: USD | D12: 6.28 | E12: 46023 | F12: 46053
A14: FEBRERO
A16: IMPORTEX MODA 2025 CTA PUBLICITARIA | B16: 10/01 DUPLICADO 09/11/2025-Cuchillo Tazaki™- ABO - 16/11/2025 | C16: USD | D16: 849.36 | E16: 46054 | F16: 46081
A17: IMPORTEX MODA 2025 CTA PUBLICITARIA | B17: 17/01/2026 - FilmPro® - CBO | C17: USD | D17: 849.16 | E17: 46054 | F17: 46081
A18: 2 IMPORTEX MODA 2025 CTA PUBLICITARIA | B18: 17/02/2026 - Cuchillo Tazaki™ - CBO | C18: USD | D18: 338.32 | E18: 46054 | F18: 46081
A19: IMPORTEX MODA 2025 CTA PUBLICITARIA | B19: 12/11/2025- FilmPro®- ABO - / DUPLICADO CBO $50 - 25/02 | C19: USD | D19: 189.58 | E19: 46054 | F19: 46081
A20: 2 IMPORTEX MODA 2025 CTA PUBLICITARIA | B20: 01/02/2026 - Llave Multifuncional 360™- CBO | C20: USD | D20: 158.89 | E20: 46054 | F20: 46081
A21: IMPORTEX MODA 2025 CTA PUBLICITARIA | B21: 27/02/2026 - FreeBeat Adapter - ABO | C21: USD | D21: 24.57 | E21: 46054 | F21: 46081

Sheet SupermetricsQueries
A1: Supermetrics Queries
A3: All the queries created by Supermetrics are stored here, each in its own row.
H4: 17707215
A5: On this sheet you can:
A6: 1. Modify the parameters of a query. Any changes will be visible when you run a refresh.
A8: 2. Remove a query by deleting its row | H8: America/Bogota
A10: 3. Add new queries: type a range address and query parameters, leave the query ID empty. The query will be added when you run a refresh. (Of course, it's much easier to use the sidebar to add new queries.)
A13: Queries are stored with the authentication of the original user that created the query. If you want to transfer a query to the currently active Google Sheets user, delete its query ID from column A and run a refresh. For complete instructions on transferring queries, see https://support.supermetrics.com/support/solutions/articles/19000050074-how-can-i-transfer-queries-from-one-user-to-another-
A16: Don't delete or rename this sheet. If you delete or rename it, your existing queries can no longer be refreshed. Hiding the sheet is OK. Also, don't delete any rows above row 21.
A19: Query ID | D19: Sheet name | E19: Range address | G19: Created | H19: Updated | I19: Last status | J19: Last refresh ID | K19: Results contain sampled data | L19: Execution time (sec) | M19: Object type | N19: Linked chart ID | O19: Data source | Q19: Date range type | R19: Start date | S19: End date | T19: Compare to | U19: Comparison value type | W19: Accounts/views | X19: Metrics | Y19: Dimensions | Z19: Pivot dimensions | AA19: Filters | AB19: Segment ID | AC19: Sort | AD19: Max rows | AE19: Max pivot categories | AF19: Special settings | AG19: Other parameters | AJ19: Result type | AK19: Language/country | AL19: Translate to | AN19: SQL | AO19: Database name | AP19: Range address (static) | AQ19: Report type | AT19: Highlight with colour | AU19: Refresh with user account | AV19: Returned data | AW19: Refresh button number
A20: paramsID | C20: ssID | D20: sheetName | E20: rangeAddress | G20: created | H20: updated | I20: lastStatus | J20: lastqueryID | K20: sampled | L20: runtime_sec | M20: objType | N20: linkedChartID | O20: dataSource | Q20: dateRangeType | R20: startDateString | S20: endDateString | T20: comp | U20: cvt | W20: profiles | X20: metrics | Y20: dimensions | Z20: sd | AA20: filterArr | AB20: segment | AC20: sort | AD20: maxResults | AE20: maxCategories | AF20: specialSettings | AG20: otherParams | AJ20: sds_result_type | AK20: sds_lang | AL20: sds_tolang | AN20: sql | AO20: db_name | AP20: rangeAddressStatic | AQ20: rt | AR20: scopeMZ | AS20: sortMZ | AT20: condform | AU20: authUser | AV20: metaDataToUser | AW20: refreshButtonNumber
A21: xhBK48cDeYRNkKTgEkN3NSS83QBpNp | D21: =IFERROR(__xludf.DUMMYFUNCTION("ARRAY_CONSTRAIN(split(CELL(""ADDRESS"",zsupermetrics_xhBK48cDeYRNkKTgEkN3NSS83QBpNp),""!""),1,1)"),"TK") -> TK | E21: =CELL("ADDRESS",zsupermetrics_xhBK48cDeYRNkKTgEkN3NSS83QBpNp)&":"&address(row(zsupermetrics_xhBK48cDeYRNkKTgEkN3NSS83QBpNp)+rows(zsupermetrics_xhBK48cDeYRNkKTgEkN3NSS83QBpNp)-1,column(zsupermetrics_xhBK48cDeYRNkKTgEkN3NSS83QBpNp)+COLUMNS(zsupermetrics_xhBK48cDeYRNkKTgEkN3NSS83QBpNp)-1) -> TK!$H$6:$S$65 | G21: 2026-01-27 18:00:03.0 | H21: 46063.253 | I21: Refreshed successfully by trigger iP2uL1zbWwAyCOtK9hl6RHQIBb4wLt | J21: 1770721480942 | K21: FALSE | L21: 12 | M21: TABLE | O21: FA | Q21: custom | R21: 46023 | S21: 46049 | W21: ["act_771085292027587`2 IMPORTEX MODA 2025 CTA PUBLICITARIA","act_2201688663608851`3 IMPORTEX 2025 CTA PUBLICITARIA ","act_3035690929930583`IMPORTEX MODA 2025 CTA PUBLICITARIA "] | X21: ["cost"] | Y21: ["Date","campaign_group_name"] | Z21: ["campaign_group_name"] | AA21: [] | AB21: [] | AD21: 10000 | AE21: 50 | AF21: ["BLANKS_TO_ZERO","SHOW_ALL_TIME_VALUES","ACTION_REPORT_TIME_conversion"] | AG21: {} | AP21: TK'!H6:S65 | AU21: 903837718759499

Sheet NOMBRE DE PRODUCTOS
A1: NOMBRE DE PRODUCTO | B1: NOMBRE COMERCIAL
A2: LLAVE TRINQUETE | B2: Llave Multifuncional 360™
A3: PARABRISA | B3: FilmPro®
A4: GEL | B4: FLORA FRESH PRO™
A5: CUCHILLO | B5: Cuchillo Tazaki™
A6: GUANTE | B6: FURBLADE™
A7: FILTRO | B7: DrainGuard Pro™
A8: Receptor Bluetooth | B8: FreeBeat Adapter
A9: JBL | B9: JBL GO 4

Sheet DEVOLUCION
A1: ID | B1: FECHA | C1: TIPO | D1: MONTO | E1: MONTO PREVIO | F1: ORDEN ID | G1: NUMERO DE GUIA | H1: DESCRIPCIÓN | I1: CUENTA | J1: CONCEPTO DE RETIRO
A2: 10115973 | B2: 28-02-2026 00:48 | C2: ENTRADA | D2: 8.66 | E2: 2518.43 | F2: 4622643 | G2: D001362823 | H2: ENTRADA POR GANANCIA EN LA ORDEN COMO DROPSHIPPER: 4622643* GUIA: *D001362823*
A3: 10115604 | B3: 28-02-2026 00:48 | C3: ENTRADA | D3: 7.61 | E3: 2510.82 | F3: 4622389 | G3: D001362824 | H3: ENTRADA POR GANANCIA EN LA ORDEN COMO DROPSHIPPER: 4622389* GUIA: *D001362824*
A4: 10108235 | B4: 28-02-2026 00:46 | C4: ENTRADA | D4: 14.34 | E4: 2496.48 | F4: 4617199 | G4: D001359468 | H4: ENTRADA POR GANANCIA EN LA ORDEN COMO DROPSHIPPER: 4617199* GUIA: *D001359468*
A5: 10090635 | B5: 28-02-2026 00:42 | C5: ENTRADA | D5: 16.79 | E5: 2479.69 | F5: 4598492 | G5: D001359560 | H5: ENTRADA POR GANANCIA EN LA ORDEN COMO DROPSHIPPER: 4598492* GUIA: *D001359560*
A6: 10084440 | B6: 28-02-2026 00:41 | C6: ENTRADA | D6: 16.79 | E6: 2462.9 | F6: 4586637 | G6: D001353667 | H6: ENTRADA POR GANANCIA EN LA ORDEN COMO DROPSHIPPER: 4586637* GUIA: *D001353667*
A7: 10084419 | B7: 28-02-2026 00:41 | C7: ENTRADA | D7: 15.95 | E7: 2446.95 | F7: 4586613 | G7: D001353670 | H7: ENTRADA POR GANANCIA EN LA ORDEN COMO DROPSHIPPER: 4586613* GUIA: *D001353670*
A8: 10084412 | B8: 28-02-2026 00:41 | C8: ENTRADA | D8: 17.83 | E8: 2429.12 | F8: 4586582 | G8: D001353673 | H8: ENTRADA POR GANANCIA EN LA ORDEN COMO DROPSHIPPER: 4586582* GUIA: *D001353673*
A9: 10084391 | B9: 28-02-2026 00:41 | C9: ENTRADA | D9: 16.79 | E9: 2412.33 | F9: 4586535 | G9: D001353675 | H9: ENTRADA POR GANANCIA EN LA ORDEN COMO DROPSHIPPER: 4586535* GUIA: *D001353675*
A10: 10081290 | B10: 28-02-2026 00:40 | C10: ENTRADA | D10: 8.66 | E10: 2403.67 | F10: 4578106 | G10: D001354500 | H10: ENTRADA POR GANANCIA EN LA ORDEN COMO DROPSHIPPER: 4578106* GUIA: *D001354500*
A11: 10080805 | B11: 28-02-2026 00:40 | C11: ENTRADA | D11: 8.66 | E11: 2395.01 | F11: 4576899 | G11: D001354509 | H11: ENTRADA POR GANANCIA EN LA ORDEN COMO DROPSHIPPER: 4576899* GUIA: *D001354509*
A12: 10074574 | B12: 28-02-2026 00:39 | C12: ENTRADA | D12: 16.64 | E12: 2378.37 | F12: 4550422 | G12: D001355665 | H12: ENTRADA POR GANANCIA EN LA ORDEN COMO DROPSHIPPER: 4550422* GUIA: *D001355665*
A13: 10074538 | B13: 28-02-2026 00:39 | C13: ENTRADA | D13: 13.45 | E13: 2364.92 | F13: 4550182 | G13: D001344693 | H13: ENTRADA POR GANANCIA EN LA ORDEN COMO DROPSHIPPER: 4550182* GUIA: *D001344693*
A14: 10074268 | B14: 28-02-2026 00:39 | C14: ENTRADA | D14: 6.8 | E14: 2358.12 | F14: 4548322 | G14: 186796386 | H14: ENTRADA POR GANANCIA EN LA ORDEN COMO DROPSHIPPER: 4548322* GUIA: *186796386*
A15: 10072050 | B15: 28-02-2026 00:38 | C15: ENTRADA | D15: 9.7 | E15: 2348.42 | F15: 4523482 | G15: D001339560 | H15: ENTRADA POR GANANCIA EN LA ORDEN COMO DROPSHIPPER: 4523482* GUIA: *D001339560*
A16: 10071828 | B16: 28-02-2026 00:38 | C16: ENTRADA | D16: 15.85 | E16: 2332.57 | F16: 4521408 | G16: D001340310 | H16: ENTRADA POR GANANCIA EN LA ORDEN COMO DROPSHIPPER: 4521408* GUIA: *D001340310*
A17: 10067051 | B17: 27-02-2026 14:04 | C17: SALIDA | D17: 7.19 | E17: 2339.76 | F17: 4507232 | G17: LC52905133 | H17: SALIDA POR COBRO DE FLETE INICIAL: 4507232
A18: 10065674 | B18: 27-02-2026 03:07 | C18: SALIDA | D18: 5.65 | E18: 2345.41 | F18: 4523515 | G18: D001339559 | H18: SALIDA DE COBRO DE DEVOLUCIÓN POR ENTREGA NO EFECTIVA: 4523515
A19: 10065673 | B19: 27-02-2026 03:07 | C19: SALIDA | D19: 5.13 | E19: 2350.54 | F19: 4523546 | G19: D001339556 | H19: SALIDA DE COBRO DE DEVOLUCIÓN POR ENTREGA NO EFECTIVA: 4523546
A20: 10064705 | B20: 27-02-2026 03:01 | C20: SALIDA | D20: 5.07 | E20: 2355.61 | F20: 4484391 | G20: D001324356 | H20: SALIDA DE COBRO DE DEVOLUCIÓN POR ENTREGA NO EFECTIVA: 4484391
A21: 10064704 | B21: 27-02-2026 03:01 | C21: SALIDA | D21: 5.13 | E21: 2360.74 | F21: 4484661 | G21: D001324354 | H21: SALIDA DE COBRO DE DEVOLUCIÓN POR ENTREGA NO EFECTIVA: 4484661
A22: 10064703 | B22: 27-02-2026 03:01 | C22: SALIDA | D22: 5.13 | E22: 2365.87 | F22: 4485107 | G22: D001324351 | H22: SALIDA DE COBRO DE DEVOLUCIÓN POR ENTREGA NO EFECTIVA: 4485107
A23: 10064701 | B23: 27-02-2026 03:01 | C23: SALIDA | D23: 5.12 | E23: 2370.99 | F23: 4486265 | G23: D001324346 | H23: SALIDA DE COBRO DE DEVOLUCIÓN POR ENTREGA NO EFECTIVA: 4486265
A24: 10064700 | B24: 27-02-2026 03:01 | C24: SALIDA | D24: 5.07 | E24: 2376.06 | F24: 4486979 | G24: D001324338 | H24: SALIDA DE COBRO DE DEVOLUCIÓN POR ENTREGA NO EFECTIVA: 4486979
A25: 10064699 | B25: 27-02-2026 03:01 | C25: SALIDA | D25: 5.07 | E25: 2381.13 | F25: 4487345 | G25: D001324337 | H25: SALIDA DE COBRO DE DEVOLUCIÓN POR ENTREGA NO EFECTIVA: 4487345
A26: 10064698 | B26: 27-02-2026 03:01 | C26: SALIDA | D26: 5.07 | E26: 2386.2 | F26: 4489045 | G26: D001324326 | H26: SALIDA DE COBRO DE DEVOLUCIÓN POR ENTREGA NO EFECTIVA: 4489045
... A30: 10064569 | B30: 27-02-2026 03:01 | C30: SALIDA | D30: 5.11 | E30: 2405.99 | F30: 4490717 | G30: D001322955 | H30: SALIDA DE COBRO DE DEVOLUCIÓN POR ENTREGA NO EFECTIVA: 4490717
A31: 10063636 | B31: 27-02-2026 01:01 | C31: SALIDA | D31: 7.67 | E31: 2413.66 | F31: 4350109 | G31: 186994371 | H31: SALIDA POR COBRO DE FLETE INICIAL: 4350109
A32: 10059773 | B32: 27-02-2026 00:53 | C32: ENTRADA | D32: 18.4 | E32: 2395.26 | F32: 4617647 | G32: D001359464 | H32: ENTRADA POR GANANCIA EN LA ORDEN COMO DROPSHIPPER: 4617647* GUIA: *D001359464*
A33: 10059512 | B33: 27-02-2026 00:53 | C33: ENTRADA | D33: 15.95 | E33: 2379.31 | F33: 4617195 | G33: D001359469 | H33: ENTRADA POR GANANCIA EN LA ORDEN COMO DROPSHIPPER: 4617195* GUIA: *D001359469*
A34: 10032750 | B34: 27-02-2026 00:46 | C34: ENTRADA | D34: 6.8 | E34: 2372.51 | F34: 4596067 | G34: 186573343 | H34: ENTRADA POR GANANCIA EN LA ORDEN COMO DROPSHIPPER: 4596067* GUIA: *186573343*
A35: 10024293 | B35: 27-02-2026 00:44 | C35: ENTRADA | D35: 17.83 | E35: 2354.68 | F35: 4586569 | G35: D001353674 | H35: ENTRADA POR GANANCIA EN LA ORDEN COMO DROPSHIPPER: 4586569* GUIA: *D001353674*
A36: 10024112 | B36: 27-02-2026 00:44 | C36: ENTRADA | D36: 7.2 | E36: 2347.48 | F36: 4586325 | G36: LC52934417 | H36: ENTRADA POR GANANCIA EN LA ORDEN COMO DROPSHIPPER: 4586325* GUIA: *LC52934417*
A37: 10018888 | B37: 27-02-2026 00:43 | C37: ENTRADA | D37: 12.65 | E37: 2334.83 | F37: 4579105 | G37: D001355719 | H37: ENTRADA POR GANANCIA EN LA ORDEN COMO DROPSHIPPER: 4579105* GUIA: *D001355719*
A38: 10009913 | B38: 27-02-2026 00:41 | C38: ENTRADA | D38: 13.45 | E38: 2321.38 | F38: 4559544 | G38: D001344685 | H38: ENTRADA POR GANANCIA EN LA ORDEN COMO DROPSHIPPER: 4559544* GUIA: *D001344685*
A39: 10007401 | B39: 27-02-2026 00:40 | C39: ENTRADA | D39: 14.16 | E39: 2307.22 | F39: 4549546 | G39: 186793629 | H39: ENTRADA POR GANANCIA EN LA ORDEN COMO DROPSHIPPER: 4549546* GUIA: *186793629*
A40: 10003829 | B40: 27-02-2026 00:40 | C40: ENTRADA | D40: 13.67 | E40: 2293.55 | F40: 4535081 | G40: D001340292 | H40: ENTRADA POR GANANCIA EN LA ORDEN COMO DROPSHIPPER: 4535081* GUIA: *D001340292*
A41: 10001604 | B41: 27-02-2026 00:39 | C41: ENTRADA | D41: 8.66 | E41: 2284.89 | F41: 4523556 | G41: D001339554 | H41: ENTRADA POR GANANCIA EN LA ORDEN COMO DROPSHIPPER: 4523556* GUIA: *D001339554*
A42: 10000114 | B42: 27-02-2026 00:39 | C42: ENTRADA | D42: 10.96 | E42: 2273.93 | F42: 4507478 | G42: D001340340 | H42: ENTRADA POR GANANCIA EN LA ORDEN COMO DROPSHIPPER: 4507478* GUIA: *D001340340*
A43: 9999795 | B43: 27-02-2026 00:38 | C43: ENTRADA | D43: 13.45 | E43: 2260.48 | F43: 4502915 | G43: D001343633 | H43: ENTRADA POR GANANCIA EN LA ORDEN COMO DROPSHIPPER: 4502915* GUIA: *D001343633*
...

Sheet PLANTILLAS
A1: PRODUCTO | B1: CONFIRMACION 1 | C1: CONFIRMACION 2 | D1: CONFIRMACION 3 | E1: NOVEDAD 1 | F1: NOVEDAD 2 | G1: NOVEDAD 3
A2: FilmPro® | B2: Hola, {NOMBRE} Queremos confirmar los detalles de tu pedido y la direccion en donde sera entregado: Producto: {CANTIDAD} {PRODUCTO} Valor: ${VALOR} Direccion: {DIRECCION}, {CIUDAD} - {PROVINCIA} Confirmanos si todo esta correcto respondiendo CONFIRMADO
A3: Cuchillo Tazaki™

Sheet PENDIENTES
A1: FECHA | B1: NOMBRE | C1: PRODUCTO | D1: ESTADO | E1: ID | F1: CONTACTO | G1: LINK WHASAPP | H1: OBSERBACIONES
A2: {=IFERROR( INDEX(FEBRERO!B:B, MATCH(E2, FEBRERO!T:T, 0)), IFERROR( INDEX(MARZO!B:B, MATCH(E2, MARZO!T:T, 0)), "" ) )} -> 46054 | B2: =IFERROR(__xludf.DUMMYFUNCTION("FILTER( { FEBRERO!C:C,FEBRERO!D:D,FEBRERO!O:O,FEBRERO!T:T; MARZO!C:C,MARZO!D:D,MARZO!O:O,MARZO!T:T }, { FEBRERO!O:O; MARZO!O:O }=""PENDIENTE"" )"),"Cristian Suarez") -> Cristian Suarez | C2: =IFERROR(__xludf.DUMMYFUNCTION("""COMPUTED_VALUE"""),"FilmPro®") -> FilmPro® | D2: =IFERROR(__xludf.DUMMYFUNCTION("""COMPUTED_VALUE"""),"PENDIENTE") -> PENDIENTE | E2: =IFERROR(__xludf.DUMMYFUNCTION("""COMPUTED_VALUE"""),4370206.0) -> 4370206 | F2: {=IF(E2:E1000="", "", "593"&VLOOKUP(E2:E1000,REPORTE_DROPI!B:F,5,FALSE) )} -> 593992766120
A3: {=IFERROR( INDEX(FEBRERO!B:B, MATCH(E3, FEBRERO!T:T, 0)), IFERROR( INDEX(MARZO!B:B, MATCH(E3, MARZO!T:T, 0)), "" ) )} -> 46054 | B3: =IFERROR(__xludf.DUMMYFUNCTION("""COMPUTED_VALUE"""),"Cecilia Tapia") -> Cecilia Tapia | C3: =IFERROR(__xludf.DUMMYFUNCTION("""COMPUTED_VALUE"""),"Cuchillo Tazaki™") -> Cuchillo Tazaki™ | D3: =IFERROR(__xludf.DUMMYFUNCTION("""COMPUTED_VALUE"""),"PENDIENTE") -> PENDIENTE | E3: =IFERROR(__xludf.DUMMYFUNCTION("""COMPUTED_VALUE"""),4348861.0) -> 4348861 | F3: 593969076621
A4: {=IFERROR( INDEX(FEBRERO!B:B, MATCH(E4, FEBRERO!T:T, 0)), IFERROR( INDEX(MARZO!B:B, MATCH(E4, MARZO!T:T, 0)), "" ) )} -> 46054 | B4: =IFERROR(__xludf.DUMMYFUNCTION("""COMPUTED_VALUE"""),"Jose Cabrera Maya Cabrera Maya") -> Jose Cabrera Maya Cabrera Maya | C4: =IFERROR(__xludf.DUMMYFUNCTION("""COMPUTED_VALUE"""),"FilmPro®") -> FilmPro® | D4: =IFERROR(__xludf.DUMMYFUNCTION("""COMPUTED_VALUE"""),"PENDIENTE") -> PENDIENTE | E4: =IFERROR(__xludf.DUMMYFUNCTION("""COMPUTED_VALUE"""),4370534.0) -> 4370534 | F4: 593983713271
A5: {=IFERROR( INDEX(FEBRERO!B:B, MATCH(E5, FEBRERO!T:T, 0)), IFERROR( INDEX(MARZO!B:B, MATCH(E5, MARZO!T:T, 0)), "" ) )} -> 46054 | B5: =IFERROR(__xludf.DUMMYFUNCTION("""COMPUTED_VALUE"""),"Fabian Molina Molina") -> Fabian Molina Molina | C5: =IFERROR(__xludf.DUMMYFUNCTION("""COMPUTED_VALUE"""),"FilmPro®") -> FilmPro® | D5: =IFERROR(__xludf.DUMMYFUNCTION("""COMPUTED_VALUE"""),"PENDIENTE") -> PENDIENTE | E5: =IFERROR(__xludf.DUMMYFUNCTION("""COMPUTED_VALUE"""),4349540.0) -> 4349540 | F5: 593983076106
A6: {=IFERROR( INDEX(FEBRERO!B:B, MATCH(E6, FEBRERO!T:T, 0)), IFERROR( INDEX(MARZO!B:B, MATCH(E6, MARZO!T:T, 0)), "" ) )} -> 46054 | B6: =IFERROR(__xludf.DUMMYFUNCTION("""COMPUTED_VALUE"""),"Wilson Guerrero") -> Wilson Guerrero | C6: =IFERROR(__xludf.DUMMYFUNCTION("""COMPUTED_VALUE"""),"FilmPro®") -> FilmPro® | D6: =IFERROR(__xludf.DUMMYFUNCTION("""COMPUTED_VALUE"""),"PENDIENTE") -> PENDIENTE | E6: =IFERROR(__xludf.DUMMYFUNCTION("""COMPUTED_VALUE"""),4349603.0) -> 4349603 | F6: 593967599083
A7: {=IFERROR( INDEX(FEBRERO!B:B, MATCH(E7, FEBRERO!T:T, 0)), IFERROR( INDEX(MARZO!B:B, MATCH(E7, MARZO!T:T, 0)), "" ) )} -> 46054 | B7: =IFERROR(__xludf.DUMMYFUNCTION("""COMPUTED_VALUE"""),"Byron Peña") -> Byron Peña | C7: =IFERROR(__xludf.DUMMYFUNCTION("""COMPUTED_VALUE"""),"FilmPro®") -> FilmPro® | D7: =IFERROR(__xludf.DUMMYFUNCTION("""COMPUTED_VALUE"""),"PENDIENTE") -> PENDIENTE | E7: =IFERROR(__xludf.DUMMYFUNCTION("""COMPUTED_VALUE"""),4351675.0) -> 4351675 | F7: 593969345643
A8: {=IFERROR( INDEX(FEBRERO!B:B, MATCH(E8, FEBRERO!T:T, 0)), IFERROR( INDEX(MARZO!B:B, MATCH(E8, MARZO!T:T, 0)), "" ) )} -> 46054 | B8: =IFERROR(__xludf.DUMMYFUNCTION("""COMPUTED_VALUE"""),"Darwin Lopez") -> Darwin Lopez | C8: =IFERROR(__xludf.DUMMYFUNCTION("""COMPUTED_VALUE"""),"FilmPro®") -> FilmPro® | D8: =IFERROR(__xludf.DUMMYFUNCTION("""COMPUTED_VALUE"""),"PENDIENTE") -> PENDIENTE | E8: =IFERROR(__xludf.DUMMYFUNCTION("""COMPUTED_VALUE"""),4352407.0) -> 4352407 | F8: 593991271195
A9: {=IFERROR( INDEX(FEBRERO!B:B, MATCH(E9, FEBRERO!T:T, 0)), IFERROR( INDEX(MARZO!B:B, MATCH(E9, MARZO!T:T, 0)), "" ) )} -> 46054 | B9: =IFERROR(__xludf.DUMMYFUNCTION("""COMPUTED_VALUE""")," Jaime Eduardo Guanopatin silva ") -> Jaime Eduardo Guanopatin silva | C9: =IFERROR(__xludf.DUMMYFUNCTION("""COMPUTED_VALUE"""),"Cuchillo Tazaki™") -> Cuchillo Tazaki™ | D9: =IFERROR(__xludf.DUMMYFUNCTION("""COMPUTED_VALUE"""),"PENDIENTE") -> PENDIENTE | E9: =IFERROR(__xludf.DUMMYFUNCTION("""COMPUTED_VALUE"""),4353478.0) -> 4353478 | F9: 593999909284
A10: {=IFERROR( INDEX(FEBRERO!B:B, MATCH(E10, FEBRERO!T:T, 0)), IFERROR( INDEX(MARZO!B:B, MATCH(E10, MARZO!T:T, 0)), "" ) )} -> 46054 | B10: =IFERROR(__xludf.DUMMYFUNCTION("""COMPUTED_VALUE"""),"LUIS BECERRA") -> LUIS BECERRA | C10: =IFERROR(__xludf.DUMMYFUNCTION("""COMPUTED_VALUE"""),"Llave Multifuncional 360™") -> Llave Multifuncional 360™ | D10: =IFERROR(__xludf.DUMMYFUNCTION("""COMPUTED_VALUE"""),"PENDIENTE") -> PENDIENTE | E10: =IFERROR(__xludf.DUMMYFUNCTION("""COMPUTED_VALUE"""),4353582.0) -> 4353582 | F10: 593994961093
A11: {=IFERROR( INDEX(FEBRERO!B:B, MATCH(E11, FEBRERO!T:T, 0)), IFERROR( INDEX(MARZO!B:B, MATCH(E11, MARZO!T:T, 0)), "" ) )} -> 46054 | B11: =IFERROR(__xludf.DUMMYFUNCTION("""COMPUTED_VALUE"""),"Anibal Tipantasi") -> Anibal Tipantasi | C11: =IFERROR(__xludf.DUMMYFUNCTION("""COMPUTED_VALUE"""),"Llave Multifuncional 360™") -> Llave Multifuncional 360™ | D11: =IFERROR(__xludf.DUMMYFUNCTION("""COMPUTED_VALUE"""),"PENDIENTE") -> PENDIENTE | E11: =IFERROR(__xludf.DUMMYFUNCTION("""COMPUTED_VALUE"""),4356452.0) -> 4356452 | F11: 593998148020
A12: {=IFERROR( INDEX(FEBRERO!B:B, MATCH(E12, FEBRERO!T:T, 0)), IFERROR( INDEX(MARZO!B:B, MATCH(E12, MARZO!T:T, 0)), "" ) )} -> 46054 | B12: =IFERROR(__xludf.DUMMYFUNCTION("""COMPUTED_VALUE"""),"Pablo De La Cruz") -> Pablo De La Cruz | C12: =IFERROR(__xludf.DUMMYFUNCTION("""COMPUTED_VALUE"""),"FilmPro®") -> FilmPro® | D12: =IFERROR(__xludf.DUMMYFUNCTION("""COMPUTED_VALUE"""),"PENDIENTE") -> PENDIENTE | E12: =IFERROR(__xludf.DUMMYFUNCTION("""COMPUTED_VALUE"""),4356619.0) -> 4356619 | F12: 593995649035
A13: {=IFERROR( INDEX(FEBRERO!B:B, MATCH(E13, FEBRERO!T:T, 0)), IFERROR( INDEX(MARZO!B:B, MATCH(E13, MARZO!T:T, 0)), "" ) )} -> 46054 | B13: =IFERROR(__xludf.DUMMYFUNCTION("""COMPUTED_VALUE"""),"Luís Zambrano ") -> Luís Zambrano | C13: =IFERROR(__xludf.DUMMYFUNCTION("""COMPUTED_VALUE"""),"Cuchillo Tazaki™") -> Cuchillo Tazaki™ | D13: =IFERROR(__xludf.DUMMYFUNCTION("""COMPUTED_VALUE"""),"PENDIENTE") -> PENDIENTE | E13: =IFERROR(__xludf.DUMMYFUNCTION("""COMPUTED_VALUE"""),4357933.0) -> 4357933 | F13: 593985391767
A14: {=IFERROR( INDEX(FEBRERO!B:B, MATCH(E14, FEBRERO!T:T, 0)), IFERROR( INDEX(MARZO!B:B, MATCH(E14, MARZO!T:T, 0)), "" ) )} -> 46054 | B14: =IFERROR(__xludf.DUMMYFUNCTION("""COMPUTED_VALUE"""),"Agripino Milciades Fernandez Nupia ") -> Agripino Milciades Fernandez Nupia | C14: =IFERROR(__xludf.DUMMYFUNCTION("""COMPUTED_VALUE"""),"Cuchillo Tazaki™") -> Cuchillo Tazaki™ | D14: =IFERROR(__xludf.DUMMYFUNCTION("""COMPUTED_VALUE"""),"PENDIENTE") -> PENDIENTE | E14: =IFERROR(__xludf.DUMMYFUNCTION("""COMPUTED_VALUE"""),4372035.0) -> 4372035 | F14: 593987912213
A15: {=IFERROR( INDEX(FEBRERO!B:B, MATCH(E15, FEBRERO!T:T, 0)), IFERROR( INDEX(MARZO!B:B, MATCH(E15, MARZO!T:T, 0)), "" ) )} -> 46054 | B15: =IFERROR(__xludf.DUMMYFUNCTION("""COMPUTED_VALUE"""),"Jimmy Villavicencio") -> Jimmy Villavicencio | C15: =IFERROR(__xludf.DUMMYFUNCTION("""COMPUTED_VALUE"""),"FilmPro®") -> FilmPro® | D15: =IFERROR(__xludf.DUMMYFUNCTION("""COMPUTED_VALUE"""),"PENDIENTE") -> PENDIENTE | E15: =IFERROR(__xludf.DUMMYFUNCTION("""COMPUTED_VALUE"""),4359740.0) -> 4359740 | F15: 593987691121
A16: {=IFERROR( INDEX(FEBRERO!B:B, MATCH(E16, FEBRERO!T:T, 0)), IFERROR( INDEX(MARZO!B:B, MATCH(E16, MARZO!T:T, 0)), "" ) )} -> 46054 | B16: =IFERROR(__xludf.DUMMYFUNCTION("""COMPUTED_VALUE"""),"María Jose Yánez") -> María Jose Yánez | C16: =IFERROR(__xludf.DUMMYFUNCTION("""COMPUTED_VALUE"""),"FilmPro®") -> FilmPro® | D16: =IFERROR(__xludf.DUMMYFUNCTION("""COMPUTED_VALUE"""),"PENDIENTE") -> PENDIENTE | E16: =IFERROR(__xludf.DUMMYFUNCTION("""COMPUTED_VALUE"""),4372193.0) -> 4372193 | F16: 593969958828
A17: {=IFERROR( INDEX(FEBRERO!B:B, MATCH(E17, FEBRERO!T:T, 0)), IFERROR( INDEX(MARZO!B:B, MATCH(E17, MARZO!T:T, 0)), "" ) )} -> 46054 | B17: =IFERROR(__xludf.DUMMYFUNCTION("""COMPUTED_VALUE"""),"Nexar Antonio Mero López") -> Nexar Antonio Mero López | C17: =IFERROR(__xludf.DUMMYFUNCTION("""COMPUTED_VALUE"""),"Llave Multifuncional 360™") -> Llave Multifuncional 360™ | D17: =IFERROR(__xludf.DUMMYFUNCTION("""COMPUTED_VALUE"""),"PENDIENTE") -> PENDIENTE | E17: =IFERROR(__xludf.DUMMYFUNCTION("""COMPUTED_VALUE"""),4360337.0) -> 4360337 | F17: 593997233084
A18: {=IFERROR( INDEX(FEBRERO!B:B, MATCH(E18, FEBRERO!T:T, 0)), IFERROR( INDEX(MARZO!B:B, MATCH(E18, MARZO!T:T, 0)), "" ) )} -> 46055 | B18: =IFERROR(__xludf.DUMMYFUNCTION("""COMPUTED_VALUE"""),"Marino Alexis RESTREPO ARCILA") -> Marino Alexis RESTREPO ARCILA | C18: =IFERROR(__xludf.DUMMYFUNCTION("""COMPUTED_VALUE"""),"FilmPro®") -> FilmPro® | D18: =IFERROR(__xludf.DUMMYFUNCTION("""COMPUTED_VALUE"""),"PENDIENTE") -> PENDIENTE | E18: =IFERROR(__xludf.DUMMYFUNCTION("""COMPUTED_VALUE"""),4360690.0) -> 4360690 | F18: 593984645032
A19: {=IFERROR( INDEX(FEBRERO!B:B, MATCH(E19, FEBRERO!T:T, 0)), IFERROR( INDEX(MARZO!B:B, MATCH(E19, MARZO!T:T, 0)), "" ) )} -> 46055 | B19: =IFERROR(__xludf.DUMMYFUNCTION("""COMPUTED_VALUE"""),"Jorge Portilla") -> Jorge Portilla | C19: =IFERROR(__xludf.DUMMYFUNCTION("""COMPUTED_VALUE"""),"Llave Multifuncional 360™") -> Llave Multifuncional 360™ | D19: =IFERROR(__xludf.DUMMYFUNCTION("""COMPUTED_VALUE"""),"PENDIENTE") -> PENDIENTE | E19: =IFERROR(__xludf.DUMMYFUNCTION("""COMPUTED_VALUE"""),4361137.0) -> 4361137 | F19: 593999646105
A20: {=IFERROR( INDEX(FEBRERO!B:B, MATCH(E20, FEBRERO!T:T, 0)), IFERROR( INDEX(MARZO!B:B, MATCH(E20, MARZO!T:T, 0)), "" ) )} -> 46055 | B20: =IFERROR(__xludf.DUMMYFUNCTION("""COMPUTED_VALUE"""),"Jose Carrillo Cedeño") -> Jose Carrillo Cedeño | C20: =IFERROR(__xludf.DUMMYFUNCTION("""COMPUTED_VALUE"""),"Cuchillo Tazaki™") -> Cuchillo Tazaki™ | D20: =IFERROR(__xludf.DUMMYFUNCTION("""COMPUTED_VALUE"""),"PENDIENTE") -> PENDIENTE | E20: =IFERROR(__xludf.DUMMYFUNCTION("""COMPUTED_VALUE"""),4362434.0) -> 4362434 | F20: 593992777624
A21: {=IFERROR( INDEX(FEBRERO!B:B, MATCH(E21, FEBRERO!T:T, 0)), IFERROR( INDEX(MARZO!B:B, MATCH(E21, MARZO!T:T, 0)), "" ) )} -> 46055 | B21: =IFERROR(__xludf.DUMMYFUNCTION("""COMPUTED_VALUE"""),"Alfonso Chacha") -> Alfonso Chacha | C21: =IFERROR(__xludf.DUMMYFUNCTION("""COMPUTED_VALUE"""),"Llave Multifuncional 360™") -> Llave Multifuncional 360™ | D21: =IFERROR(__xludf.DUMMYFUNCTION("""COMPUTED_VALUE"""),"PENDIENTE") -> PENDIENTE | E21: =IFERROR(__xludf.DUMMYFUNCTION("""COMPUTED_VALUE"""),4363609.0) -> 4363609 | F21: 593995414068
A22: {=IFERROR( INDEX(FEBRERO!B:B, MATCH(E22, FEBRERO!T:T, 0)), IFERROR( INDEX(MARZO!B:B, MATCH(E22, MARZO!T:T, 0)), "" ) )} -> 46055 | B22: =IFERROR(__xludf.DUMMYFUNCTION("""COMPUTED_VALUE"""),"Luis Rubén") -> Luis Rubén | C22: =IFERROR(__xludf.DUMMYFUNCTION("""COMPUTED_VALUE"""),"FilmPro®") -> FilmPro® | D22: =IFERROR(__xludf.DUMMYFUNCTION("""COMPUTED_VALUE"""),"PENDIENTE") -> PENDIENTE | E22: =IFERROR(__xludf.DUMMYFUNCTION("""COMPUTED_VALUE"""),4363816.0) -> 4363816 | F22: 593993223824
A23: {=IFERROR( INDEX(FEBRERO!B:B, MATCH(E23, FEBRERO!T:T, 0)), IFERROR( INDEX(MARZO!B:B, MATCH(E23, MARZO!T:T, 0)), "" ) )} -> 46055 | B23: =IFERROR(__xludf.DUMMYFUNCTION("""COMPUTED_VALUE"""),"Jose luis ibujes") -> Jose luis ibujes | C23: =IFERROR(__xludf.DUMMYFUNCTION("""COMPUTED_VALUE"""),"Llave Multifuncional 360™") -> Llave Multifuncional 360™ | D23: =IFERROR(__xludf.DUMMYFUNCTION("""COMPUTED_VALUE"""),"PENDIENTE") -> PENDIENTE | E23: =IFERROR(__xludf.DUMMYFUNCTION("""COMPUTED_VALUE"""),4364765.0) -> 4364765 | F23: 593994181004
A24: {=IFERROR( INDEX(FEBRERO!B:B, MATCH(E24, FEBRERO!T:T, 0)), IFERROR( INDEX(MARZO!B:B, MATCH(E24, MARZO!T:T, 0)), "" ) )} -> 46058 | B24: =IFERROR(__xludf.DUMMYFUNCTION("""COMPUTED_VALUE"""),"Franklin Mauricio Sanmartín Fajardo") -> Franklin Mauricio Sanmartín Fajardo | C24: =IFERROR(__xludf.DUMMYFUNCTION("""COMPUTED_VALUE"""),"Cuchillo Tazaki™") -> Cuchillo Tazaki™ | D24: =IFERROR(__xludf.DUMMYFUNCTION("""COMPUTED_VALUE"""),"PENDIENTE") -> PENDIENTE | E24: =IFERROR(__xludf.DUMMYFUNCTION("""COMPUTED_VALUE"""),4404690.0) -> 4404690 | F24: 593988810361
A25: {=IFERROR( INDEX(FEBRERO!B:B, MATCH(E25, FEBRERO!T:T, 0)), IFERROR( INDEX(MARZO!B:B, MATCH(E25, MARZO!T:T, 0)), "" ) )} -> 46058 | B25: =IFERROR(__xludf.DUMMYFUNCTION("""COMPUTED_VALUE"""),"Verónica Moncayo") -> Verónica Moncayo | C25: =IFERROR(__xludf.DUMMYFUNCTION("""COMPUTED_VALUE"""),"FilmPro®") -> FilmPro® | D25: =IFERROR(__xludf.DUMMYFUNCTION("""COMPUTED_VALUE"""),"PENDIENTE") -> PENDIENTE | E25: =IFERROR(__xludf.DUMMYFUNCTION("""COMPUTED_VALUE"""),4405388.0) -> 4405388 | F25: 593983960630
A26: {=IFERROR( INDEX(FEBRERO!B:B, MATCH(E26, FEBRERO!T:T, 0)), IFERROR( INDEX(MARZO!B:B, MATCH(E26, MARZO!T:T, 0)), "" ) )} -> 46058 | B26: =IFERROR(__xludf.DUMMYFUNCTION("""COMPUTED_VALUE"""),"Gabriela Estefanía Vince mora 0981673958") -> Gabriela Estefanía Vince mora 0981673958 | C26: =IFERROR(__xludf.DUMMYFUNCTION("""COMPUTED_VALUE"""),"FilmPro®") -> FilmPro® | D26: =IFERROR(__xludf.DUMMYFUNCTION("""COMPUTED_VALUE"""),"PENDIENTE") -> PENDIENTE | E26: =IFERROR(__xludf.DUMMYFUNCTION("""COMPUTED_VALUE"""),4406660.0) -> 4406660 | F26: 593981673958
A27: {=IFERROR( INDEX(FEBRERO!B:B, MATCH(E27, FEBRERO!T:T, 0)), IFERROR( INDEX(MARZO!B:B, MATCH(E27, MARZO!T:T, 0)), "" ) )} -> 46058 | B27: =IFERROR(__xludf.DUMMYFUNCTION("""COMPUTED_VALUE"""),"Alexis Mero") -> Alexis Mero | C27: =IFERROR(__xludf.DUMMYFUNCTION("""COMPUTED_VALUE"""),"FilmPro®") -> FilmPro® | D27: =IFERROR(__xludf.DUMMYFUNCTION("""COMPUTED_VALUE"""),"PENDIENTE") -> PENDIENTE | E27: =IFERROR(__xludf.DUMMYFUNCTION("""COMPUTED_VALUE"""),4418776.0) -> 4418776 | F27: 593998844838
A28: {=IFERROR( INDEX(FEBRERO!B:B, MATCH(E28, FEBRERO!T:T, 0)), IFERROR( INDEX(MARZO!B:B, MATCH(E28, MARZO!T:T, 0)), "" ) )} -> 46058 | B28: =IFERROR(__xludf.DUMMYFUNCTION("""COMPUTED_VALUE"""),"Tito Andrade") -> Tito Andrade | C28: =IFERROR(__xludf.DUMMYFUNCTION("""COMPUTED_VALUE"""),"Cuchillo Tazaki™") -> Cuchillo Tazaki™ | D28: =IFERROR(__xludf.DUMMYFUNCTION("""COMPUTED_VALUE"""),"PENDIENTE") -> PENDIENTE | E28: =IFERROR(__xludf.DUMMYFUNCTION("""COMPUTED_VALUE"""),4418766.0) -> 4418766 | F28: 593993044886
A29: {=IFERROR( INDEX(FEBRERO!B:B, MATCH(E29, FEBRERO!T:T, 0)), IFERROR( INDEX(MARZO!B:B, MATCH(E29, MARZO!T:T, 0)), "" ) )} -> 46058 | B29: =IFERROR(__xludf.DUMMYFUNCTION("""COMPUTED_VALUE"""),"Erik Obando") -> Erik Obando | C29: =IFERROR(__xludf.DUMMYFUNCTION("""COMPUTED_VALUE"""),"FilmPro®") -> FilmPro® | D29: =IFERROR(__xludf.DUMMYFUNCTION("""COMPUTED_VALUE"""),"PENDIENTE") -> PENDIENTE | E29: =IFERROR(__xludf.DUMMYFUNCTION("""COMPUTED_VALUE"""),4420847.0) -> 4420847 | F29: 593998930648
A30: {=IFERROR( INDEX(FEBRERO!B:B, MATCH(E30, FEBRERO!T:T, 0)), IFERROR( INDEX(MARZO!B:B, MATCH(E30, MARZO!T:T, 0)), "" ) )} -> 46058 | B30: =IFERROR(__xludf.DUMMYFUNCTION("""COMPUTED_VALUE"""),"Hugo Espinoza") -> Hugo Espinoza | C30: =IFERROR(__xludf.DUMMYFUNCTION("""COMPUTED_VALUE"""),"FilmPro®") -> FilmPro® | D30: =IFERROR(__xludf.DUMMYFUNCTION("""COMPUTED_VALUE"""),"PENDIENTE") -> PENDIENTE | E30: =IFERROR(__xludf.DUMMYFUNCTION("""COMPUTED_VALUE"""),4418744.0) -> 4418744 | F30: 593996124553
